Workbook

Sheet Compte de résultat
A1: Hyphothèse normale : | G1: CA prévisionnel | H1: N | I1: N+1 | J1: N+2 | M1: N | N1: N+1 | O1: N +2
A2: Exploitation | B2: compte de résultat prévisionnel | C2: N | D2: N+1 | E2: N+2 | G2: CA Total | H2: =$M2*10 -> 451750 | I2: =$M2*10 -> 451750 | J2: =$M2*10 -> 451750 | L2: CA à l'année sur 10 mois | M2: =45175 -> 45175 | N2: =45175 -> 45175 | O2: =45175 -> 45175
A3: On part de l'hypothèse que le click and collect représente 65% du CA actuel (donnée de l'enquête 65% des clients sont intéressés par le click and collect), Le CA total est de 45 000/mois. Le Clik and collect réprésente 29k et on prévoit une augmentation de 5% la première année due au nouveau client intéresser par ce nouveau service ( résultat de l'étude de marché) puis 7,5% et enfin 10%. | B3: CA | C3: {=+H5:J5} -> 308319.38 | D3: 331443.33 | E3: 364587.66 | G3: CA Click and collect | H3: =H2*0.65 -> 293637.5 | I3: =I2*0.65 -> 293637.5 | J3: =J2*0.65 -> 293637.5 | L3: CA Click and collect à l'année/10mois | M3: =(M2*0.65)*1.05 -> 30831.938 | N3: =M3*1.075 -> 33144.333 | O3: =N3*1.1 -> 36458.766
A4: Les MP correspondent à l'ensemble des produits nécessaires à la vente (salade, sandwich, boissons, viennoiserie, pâtisserie, légumes… Les MP représentent 278k/ par an au total et à 65% du CA = 189 k. Ils augmentent de la même facon que le CA (5%;7,5%;10%) | B4: MP | C4: =C29 -> 189735 | D4: =D29 -> 194252.5 | E4: =E29 -> 198770 | G4: Augmentation Click and collect | H4: 0.05 | I4: 0.075 | J4: 0.1
B5: MCV | C5: =C3-C4 -> 118584.38 | D5: =D3-D4 -> 137190.83 | E5: =E3-E4 -> 165817.66 | G5: CA | H5: =H3*1.05 -> 308319.38 | I5: =H5*1.075 -> 331443.33 | J5: =I5*1.1 -> 364587.66
B6: charges externes | C6: =SUM(C7:C13) -> 55506.789 | D6: =SUM(D7:D13) -> 59066.423 | E6: =SUM(E7:E13) -> 64168.566
A7: La consommation d'électricité total du studio est de 1 1 80 0 00 kwh à 0,04992 le prix du kwh (un tarif préférentiel) soit 58k/ans. La consommation d'électricité du C&C est de 40k elle correspond à 65% de la consommation totale et augmente de la même manière que le CA. C'est la plus grosse charge. | B7: électricité | C7: =C45 -> 40210.363 | D7: =D45 -> 43226.14 | E7: =E45 -> 47548.754 | H7: =I7*H8 -> 29363750 | I7: =H3 -> 293637.5
A8: En moyenne héberger un site de notre taille coûte 150euros/ans. La location du nom de domaine sera de 15euros/ans | B8: Hébergement site | C8: =150+15 -> 165 | D8: =150+15 -> 165 | E8: =150+15 -> 165 | H8: 100 | I8: =J5 -> 364587.66
A9: Assurance multirisque professionnelle : couvre les dommages causés aux locaux, matériel et stock, ainsi que les pertes financières résultant d'une interruption d'activité due à un sinistre. + Assurance cyber-risques : protége contre les cyberattaques, les pertes de données et les violations de la confidentialité.Elle peut également couvrir les pertes financières résultant d'une interruption d'activité due à une cyberattaque. | B9: Assurances | C9: =2400 -> 2400 | D9: =C9 -> 2400 | E9: =D9 -> 2400 | H9: =H7/I8 -> 80.539615
A10: La consommation d'eau est de 220m³ d'eau au total. Pour le click and collect elle sera de 143m³ elle augmente de la même façon que le CA tous les ans au prix de 0,002840. par litre | B10: Eau | C10: 426.426 | D10: 458.40795 | E10: 504.24875
A11: Le prix d'un abonnement internet coûte environ 20 euros celui du téléphone 20 euros il ne concernera que l'employé du C&C | B11: Frais de communication tel et wifi | C11: =40*12 -> 480 | D11: =40*12 -> 480 | E11: =40*12 -> 480
A12: Le budjet marketing a été estimé à 16% du CA | B12: Communication/ Marketing | C12: 5000 | D12: 5000 | E12: 5000
A13: La consommation de gaz total est de 125Mwh à 80 euros le Mwh(=électricité). Elle augmenter comme le CA | B13: Gaz | C13: =C61 -> 6825 | D13: =D61 -> 7336.875 | E13: =E61 -> 8070.5625 | G13: Taux de marge EBE /VA
B14: VA | C14: =C5-C6 -> 63077.586 | D14: =D5-D6 -> 78124.405 | E14: =E5-E6 -> 101649.1 | G14: =C18/C14 -> 0.51743781
A15: Un salarié à temps plein embauché à 6% au-dessus du Smic en raison de l'inflation et augmenter de 2% chaque année. Cotisation patronale de 40%. La salariée sera chargée de tout le click and collect (prise de commande, réalisation de commande, suivie des commandes.... | B15: Masse salariale | C15: =+SUM(C16:C17) -> 30438.858 | D15: =+SUM(D16:D17) -> 31047.635 | E15: =+SUM(E16:E17) -> 31668.588
B16: salaires | C16: {=C69:E70} -> 21742.042 | D16: 22176.882 | E16: 22620.42
B17: cotisations patronales | C17: 8696.8166 | D17: 8870.753 | E17: 9048.168
B18: EBE | C18: =C5-C6-C15 -> 32638.728 | D18: =D5-D6-D15 -> 47076.769 | E18: =E5-E6-E15 -> 69980.507
A19: Il n'y a pas de charges financières car nous ne réaliserons aucun emprunt. En effet nous passerons par les subventions. | B19: Charges financières
B20: Dotations sur immobilisations | C20: =154+2000+2140 -> 4294 | D20: =154+2000+2140 -> 4294 | E20: =154+2000+2140 -> 4294
B21: RCAI | C21: =+C18-SUM(C19:C20) -> 28344.728 | D21: =+D18-SUM(D19:D20) -> 42782.769 | E21: =+E18-SUM(E19:E20) -> 65686.507
B22: IS | C22: =C21*0.25 -> 7086.1819 | D22: =D21*0.25 -> 10695.692 | E22: =E21*0.25 -> 16421.627
B23: Résultat net | C23: =+C21-C22 -> 21258.546 | D23: =+D21-D22 -> 32087.077 | E23: =+E21-E22 -> 49264.88
B25: MP | C25: N | D25: N+1 | E25: N+2
B26: MP TOTAL | C26: =27800*10 -> 278000 | D26: =27800*10 -> 278000 | E26: =27800*10 -> 278000
B27: MP Click and collect | C27: =C26*0.65 -> 180700 | D27: =D26*0.65 -> 180700 | E27: =E26*0.65 -> 180700
B28: Augmentation | C28: 0.05 | D28: 0.075 | E28: 0.1
B29: MP | C29: =C27*1.05 -> 189735 | D29: =D27*1.075 -> 194252.5 | E29: =E27*1.1 -> 198770 | G29: Assurance Multirisque pro | I29: Assurance Cyber-attaque
G30: Superficie | H30: 700 | I30: Prix | J30: 33
B31: Électricité | G31: Prix | H31: 166 | I31: Prix à l'année | J31: 400
B32: Mois | C32: Conso kw | D32: Prix conso kw/h | E32: Total | G32: Prix à l'année | H32: 2000
B33: Janvier | C33: 151501 | D33: 0.04992 | E33: =C33*D33 -> 7562.9299
B34: février | C34: 116940 | D34: 0.04992 | E34: =C34*D34 -> 5837.6448
B35: mars | C35: 131255 | D35: 0.04992 | E35: =C35*D35 -> 6552.2496
B36: avril | C36: 108556 | D36: 0.04992 | E36: =C36*D36 -> 5419.1155
B37: mai | C37: 101355 | D37: 0.04992 | E37: =C37*D37 -> 5059.6416
B38: juin | C38: 86489 | D38: 0.04992 | E38: =C38*D38 -> 4317.5309
B39: septembre | C39: 102073 | D39: 0.04992 | E39: =C39*D39 -> 5095.4842
B40: octobre | C40: 119990 | D40: 0.04992 | E40: =C40*D40 -> 5989.9008
B41: novembre | C41: 130460 | D41: 0.04992 | E41: =C41*D41 -> 6512.5632
...

Sheet Seuil de rentabilité
A2: CA | B2: ='Compte de résultat'!C3 -> 308319.38
A3: Charges Variables | B3: ='Compte de résultat'!C4+'Compte de résultat'!C7+'Compte de résultat'!C10+'Seuil de rentabilité'!C13 -> 230371.79
A4: Marge sur CV | B4: =B2-B3 -> 77947.586
A5: Taux de marge sur CV | B5: =B4/B2 -> 0.25281443
A6: Charges fixes | B6: ='Compte de résultat'!C8+'Compte de résultat'!C9+'Compte de résultat'!C11+'Compte de résultat'!C12+'Compte de résultat'!C16+'Compte de résultat'!C17 -> 38483.858
A7: Seuil de rentabilité | B7: =B6/B5 -> 152221.77
A9: Le chiffre d'affaires minimum à réaliser pour être rentable est donc de 152 221 euros
A12: Point mort : | B12: =(B7/B2)*360 -> 177.73724 | D12: Info : | E12: 300j/CA car vacance en juillet août
A14: L'activités devient rentable à partir du 177j

Sheet Compte de résultat Hyphotèse P
A1: Hyphothèse Pessimiste: | G1: CA prévisionnel | H1: N | I1: N+1 | J1: N+2 | M1: N | N1: N+1 | O1: N +2
A2: Exploitation | B2: compte de résultat prévisionnel | C2: N | D2: N+1 | E2: N+2 | G2: CA Total | H2: =$M2*10 -> 451750 | I2: =$M2*10 -> 451750 | J2: =$M2*10 -> 451750 | L2: CA à l'année sur 10 mois | M2: =45175 -> 45175 | N2: =45175 -> 45175 | O2: =45175 -> 45175
A3: L'hypothèse pessimiste suggére que l'introduction d'un service de click and collect ne permet aucune nouvelle affluence de la clientèle ainsi le CA ne change pas malgré les investissements faits. | B3: CA | C3: {=+H4:J4} -> 293637.5 | D3: 293637.5 | E3: 293637.5 | G3: CA Click and collect | H3: =H2*0.65 -> 293637.5 | I3: =I2*0.65 -> 293637.5 | J3: =J2*0.65 -> 293637.5 | L3: CA Click and collect à l'année/10mois | M3: =(M2*0.65)*1.05 -> 30831.938 | N3: =M3*1.075 -> 33144.333 | O3: =N3*1.1 -> 36458.766
A4: Les MP correspondent à l'ensemble des produits nécessaires à la vente (salade, sandwich, boissons, viennoiserie, pâtisserie, légumes… Les MP représentent 278k/ par an au total et à 65% du CA = 189 k. Ils augmentent de la même facon que le CA. | B4: MP | C4: =C26 -> 180700 | D4: =D26 -> 180700 | E4: =E26 -> 180700 | G4: CA | H4: =H3 -> 293637.5 | I4: =I3 -> 293637.5 | J4: =J3 -> 293637.5
B5: MCV | C5: =C3-C4 -> 112937.5 | D5: =D3-D4 -> 112937.5 | E5: =E3-E4 -> 112937.5
B6: charges externes | C6: =SUM(C7:C13) -> 53246.704 | D6: =SUM(D7:D13) -> 53246.704 | E6: =SUM(E7:E13) -> 53246.704
A7: La consommation d'électricité total du studio est de 1 1 80 0 00 kwh à 0,04992 le prix du kwh (un tarif préférentiel) soit 58k/ans. La consommation d'électricité du C&C est de 40k elle correspond à 65% de la consommation totale et augmente de la même manière que le CA. C'est la plus grosse charge. | B7: électricité | C7: =E42*0.65 -> 38295.584 | D7: =C7 -> 38295.584 | E7: =D7 -> 38295.584
A8: En moyenne héberger un site de notre taille coûte 150euros/ans. La location du nom de domaine sera de 15euros/ans | B8: Hébergement site | C8: =150+15 -> 165 | D8: =150+15 -> 165 | E8: =150+15 -> 165
A9: Assurance multirisque professionnelle : couvre les dommages causés aux locaux, matériel et stock, ainsi que les pertes financières résultant d'une interruption d'activité due à un sinistre. + Assurance cyber-risques : protége contre les cyberattaques, les pertes de données et les violations de la confidentialité.Elle peut également couvrir les pertes financières résultant d'une interruption d'activité due à une cyberattaque. | B9: Assurances | C9: =2400 -> 2400 | D9: =C9 -> 2400 | E9: =D9 -> 2400
A10: La consommation d'eau est de 220m³ d'eau au total. Pour le click and collect elle sera de 143m³ elle augmente de la même façon que le CA tous les ans au prix de 0,002840. par litre | B10: Eau | C10: =C51 -> 406.12 | D10: =D51 -> 406.12 | E10: =E51 -> 406.12
A11: Le prix d'un abonnement internet coûte environ 20 euros celui du téléphone 20 euros il ne concernera que l'employé du C&C | B11: Frais de communication tel et wifi | C11: =40*12 -> 480 | D11: =40*12 -> 480 | E11: =40*12 -> 480
A12: Le budjet marketing a été estimé à 16% du CA | B12: Communication/ Marketing | C12: 5000 | D12: 5000 | E12: 5000
A13: La consommation de gaz total est de 125Mwh à 80 euros le Mwh(=électricité). Elle augmenter comme le CA | B13: Gaz | C13: =C58 -> 6500 | D13: =D58 -> 6500 | E13: =E58 -> 6500
A14: Un salarié à temps plein embauché à 6% au-dessus du Smic en raison de l'inflation et augmenter de 2% chaque année. Cotisation patronale de 40%. La salariée sera chargée de tout le click and collect (prise de commande, réalisation de commande, suivie des commandes.... | B14: Masse salariale | C14: =+SUM(C15:C16) -> 30438.858 | D14: =+SUM(D15:D16) -> 31047.635 | E14: =+SUM(E15:E16) -> 31668.588
B15: salaires | C15: {=C66:E67} -> 21742.042 | D15: 22176.882 | E15: 22620.42
B16: cotisations patronales | C16: 8696.8166 | D16: 8870.753 | E16: 9048.168
B17: EBE | C17: =C5-C6-C14 -> 29251.938 | D17: =D5-D6-D14 -> 28643.161 | E17: =E5-E6-E14 -> 28022.208
A18: Il n'y a pas de charges financières car nous ne réaliserons aucun emprunt. En effet nous passerons par les subventions. | B18: Charges financières
B19: Dotations sur immobilisations | C19: =154+2000+2140 -> 4294 | D19: =154+2000+2140 -> 4294 | E19: =154+2000+2140 -> 4294
B20: RCAI | C20: =+C17-SUM(C18:C19) -> 24957.938 | D20: =+D17-SUM(D18:D19) -> 24349.161 | E20: =+E17-SUM(E18:E19) -> 23728.208
B21: IS | C21: =C20*0.25 -> 6239.4845 | D21: =D20*0.25 -> 6087.2902 | E21: =E20*0.25 -> 5932.052
B22: Résultat net | C22: =+C20-C21 -> 18718.453 | D22: =+D20-D21 -> 18261.871 | E22: =+E20-E21 -> 17796.156
G23: Assurance Cyber-attaque
B24: MP | C24: N | D24: N+1 | E24: N+2 | G24: Prix | H24: 33
B25: MP TOTAL | C25: =27800*10 -> 278000 | D25: =27800*10 -> 278000 | E25: =27800*10 -> 278000 | G25: Prix à l'année | H25: 400
B26: MP Click and collect | C26: =C25*0.65 -> 180700 | D26: =D25*0.65 -> 180700 | E26: =E25*0.65 -> 180700
B27: Augmentation | C27: 0.05 | D27: 0.075 | E27: 0.1
B28: MP | C28: =C26*1.05 -> 189735 | D28: =D26*1.075 -> 194252.5 | E28: =E26*1.1 -> 198770 | G28: Assurance Multirisque pro
G29: Superficie | H29: 700
B30: Électricité | G30: Prix | H30: 166
B31: Mois | C31: Conso kw | D31: Prix conso kw/h | E31: Total | G31: Prix à l'année | H31: 2000
B32: Janvier | C32: 151501 | D32: 0.04992 | E32: =C32*D32 -> 7562.9299
B33: février | C33: 116940 | D33: 0.04992 | E33: =C33*D33 -> 5837.6448
B34: mars | C34: 131255 | D34: 0.04992 | E34: =C34*D34 -> 6552.2496
B35: avril | C35: 108556 | D35: 0.04992 | E35: =C35*D35 -> 5419.1155
B36: mai | C36: 101355 | D36: 0.04992 | E36: =C36*D36 -> 5059.6416
B37: juin | C37: 86489 | D37: 0.04992 | E37: =C37*D37 -> 4317.5309
B38: septembre | C38: 102073 | D38: 0.04992 | E38: =C38*D38 -> 5095.4842
B39: octobre | C39: 119990 | D39: 0.04992 | E39: =C39*D39 -> 5989.9008
B40: novembre | C40: 130460 | D40: 0.04992 | E40: =C40*D40 -> 6512.5632
...

Sheet Compte de résultat H Optimiste
A1: Hyphothèse Optimiste : | G1: CA prévisionnel | H1: N | I1: N+1 | J1: N+2 | M1: N | N1: N+1 | O1: N +2
A2: Exploitation | B2: compte de résultat prévisionnel | C2: N | D2: N+1 | E2: N+2 | G2: CA Total | H2: =$M2*10 -> 451750 | I2: =$M2*10 -> 451750 | J2: =$M2*10 -> 451750 | L2: CA à l'année sur 10 mois | M2: =45175 -> 45175 | N2: =45175 -> 45175 | O2: =45175 -> 45175
A3: Le service de click and collecte fais un carton et permet d'augmenter la clientèle de 10% en N puis 15% en N+1 et enfin 20% en N+2. | B3: CA | C3: {=+H5:J5} -> 323001.25 | D3: 371451.44 | E3: 445741.72 | G3: CA Click and collect | H3: =H2*0.65 -> 293637.5 | I3: =I2*0.65 -> 293637.5 | J3: =J2*0.65 -> 293637.5 | L3: CA Click and collect à l'année/10mois | M3: =(M2*0.65)*1.05 -> 30831.938 | N3: =M3*1.075 -> 33144.333 | O3: =N3*1.1 -> 36458.766
A4: Les MP correspondent à l'ensemble des produits nécessaires à la vente (salade, sandwich, boissons, viennoiserie, pâtisserie, légumes… Les MP représentent 278k/ par an au total et à 65% du CA = 189 k. Ils augmentent de la même facon que le CA (5%;7,5%;10%) | B4: MP | C4: =C28 -> 198770 | D4: =D28 -> 207805 | E4: =E28 -> 216840 | G4: Augmentation Click and collect | H4: 0.1 | I4: 0.15 | J4: 0.2
B5: MCV | C5: =C3-C4 -> 124231.25 | D5: =D3-D4 -> 163646.44 | E5: =E3-E4 -> 228901.72 | G5: CA | H5: =H3*1.1 -> 323001.25 | I5: =H5*1.15 -> 371451.44 | J5: =I5*1.2 -> 445741.72
B6: charges externes | C6: =SUM(C7:C13) -> 57766.874 | D6: =SUM(D7:D13) -> 65225.155 | E6: =SUM(E7:E13) -> 76661.186
A7: La consommation d'électricité total du studio est de 1 1 80 0 00 kwh à 0,04992 le prix du kwh (un tarif préférentiel) soit 58k/ans. La consommation d'électricité du C&C est de 40k elle correspond à 65% de la consommation totale et augmente de la même manière que le CA. C'est la plus grosse charge. | B7: électricité | C7: =C44 -> 42125.142 | D7: =D44 -> 48443.914 | E7: =E44 -> 58132.696 | H7: =I7*H8 -> 29363750 | I7: =H3 -> 293637.5
A8: En moyenne héberger un site de notre taille coûte 150euros/ans. La location du nom de domaine sera de 15euros/ans | B8: Hébergement site | C8: =150+15 -> 165 | D8: =150+15 -> 165 | E8: =150+15 -> 165 | H8: 100 | I8: =J5 -> 445741.72
A9: Assurance multirisque professionnelle : couvre les dommages causés aux locaux, matériel et stock, ainsi que les pertes financières résultant d'une interruption d'activité due à un sinistre. + Assurance cyber-risques : protége contre les cyberattaques, les pertes de données et les violations de la confidentialité.Elle peut également couvrir les pertes financières résultant d'une interruption d'activité due à une cyberattaque. | B9: Assurances | C9: =2400 -> 2400 | D9: =C9 -> 2400 | E9: =D9 -> 2400 | H9: =H7/I8 -> 65.876153
A10: La consommation d'eau est de 220m³ d'eau au total. Pour le click and collect elle sera de 143m³ elle augmente de la même façon que le CA tous les ans au prix de 0,002840. par litre | B10: Eau | C10: =C52 -> 446.732 | D10: =D52 -> 513.7418 | E10: =E52 -> 616.49016
A11: Le prix d'un abonnement internet coûte environ 20 euros celui du téléphone 20 euros il ne concernera que l'employé du C&C | B11: Frais de communication tel et wifi | C11: =40*12 -> 480 | D11: =40*12 -> 480 | E11: =40*12 -> 480
A12: Le budjet marketing a été estimé à 16% du CA | B12: Communication/ Marketing | C12: 5000 | D12: 5000 | E12: 5000
A13: La consommation de gaz total est de 125Mwh à 80 euros le Mwh(=électricité). Elle augmenter comme le CA | B13: Gaz | C13: =C60 -> 7150 | D13: =D60 -> 8222.5 | E13: =E60 -> 9867
A14: Un salarié à temps plein embauché à 6% au-dessus du Smic en raison de l'inflation et augmenter de 2% chaque année. Cotisation patronale de 40%. La salariée sera chargée de tout le click and collect (prise de commande, réalisation de commande, suivie des commandes.... | B14: Masse salariale | C14: =+SUM(C15:C16) -> 30438.858 | D14: =+SUM(D15:D16) -> 31047.635 | E14: =+SUM(E15:E16) -> 31668.588
B15: salaires | C15: {=C68:E69} -> 21742.042 | D15: 22176.882 | E15: 22620.42
B16: cotisations patronales | C16: 8696.8166 | D16: 8870.753 | E16: 9048.168
B17: EBE | C17: =C5-C6-C14 -> 36025.518 | D17: =D5-D6-D14 -> 67373.647 | E17: =E5-E6-E14 -> 120571.95
A18: Il n'y a pas de charges financières car nous ne réaliserons aucun emprunt. En effet nous passerons par les subventions. | B18: Charges financières
B19: Dotations sur immobilisations | C19: =154+2000+2140 -> 4294 | D19: =154+2000+2140 -> 4294 | E19: =154+2000+2140 -> 4294
B20: RCAI | C20: =+C17-SUM(C18:C19) -> 31731.518 | D20: =+D17-SUM(D18:D19) -> 63079.647 | E20: =+E17-SUM(E18:E19) -> 116277.95
B21: IS | C21: =C20*0.25 -> 7932.8794 | D21: =D20*0.25 -> 15769.912 | E21: =E20*0.25 -> 29069.488
B22: Résultat net | C22: =+C20-C21 -> 23798.638 | D22: =+D20-D21 -> 47309.735 | E22: =+E20-E21 -> 87208.463
B24: MP | C24: N | D24: N+1 | E24: N+2
B25: MP TOTAL | C25: =27800*10 -> 278000 | D25: =27800*10 -> 278000 | E25: =27800*10 -> 278000
B26: MP Click and collect | C26: =C25*0.65 -> 180700 | D26: =D25*0.65 -> 180700 | E26: =E25*0.65 -> 180700
B27: Augmentation | C27: 0.05 | D27: 0.075 | E27: 0.1
B28: MP | C28: =C26*1.1 -> 198770 | D28: =D26*1.15 -> 207805 | E28: =E26*1.2 -> 216840
G29: Assurance Multirisque pro | I29: Assurance Cyber-attaque
B30: Électricité | G30: Superficie | H30: 700 | I30: Prix | J30: 33
B31: Mois | C31: Conso kw | D31: Prix conso kw/h | E31: Total | G31: Prix | H31: 166 | I31: Prix à l'année | J31: 400
B32: Janvier | C32: 151501 | D32: 0.04992 | E32: =C32*D32 -> 7562.9299 | G32: Prix à l'année | H32: 2000
B33: février | C33: 116940 | D33: 0.04992 | E33: =C33*D33 -> 5837.6448
B34: mars | C34: 131255 | D34: 0.04992 | E34: =C34*D34 -> 6552.2496
B35: avril | C35: 108556 | D35: 0.04992 | E35: =C35*D35 -> 5419.1155
B36: mai | C36: 101355 | D36: 0.04992 | E36: =C36*D36 -> 5059.6416
B37: juin | C37: 86489 | D37: 0.04992 | E37: =C37*D37 -> 4317.5309
B38: septembre | C38: 102073 | D38: 0.04992 | E38: =C38*D38 -> 5095.4842
B39: octobre | C39: 119990 | D39: 0.04992 | E39: =C39*D39 -> 5989.9008
B40: novembre | C40: 130460 | D40: 0.04992 | E40: =C40*D40 -> 6512.5632
B41: décembre | C41: 131595 | D41: 0.04992 | E41: =C41*D41 -> 6569.2224
...

Sheet Amortissement
A1: Entrées
A2: Investissements | B2: N | C2: N+1 | D2: N+2
A3: Étuve | B3: 1000
A4: Site internet | B4: 10000
A5: Imprimante | B5: 70
A6: Chambre froide | B6: 9400
A7: Contenaire isoterme | B7: 300
A8: Comptoir avec caisse enregistreuse | B8: 700
A9: total | B9: =SUM(B3:B8) -> 21470
A11: Tableau d'amortissement : Comptoir caisse enregistreuse + imprimante
A12: Année | B12: VR | C12: Amortissements | D12: VNC
A13: 1 | B13: 770 | C13: =B13/A17 -> 154 | D13: =B13-C13 -> 616
A14: 2 | B14: =B13-C13 -> 616 | C14: 154 | D14: =B14-C14 -> 462
A15: 3 | B15: =B14-C14 -> 462 | C15: 154 | D15: =B15-C15 -> 308
A16: 4 | B16: =B15-C15 -> 308 | C16: 154 | D16: =B16-C16 -> 154
A17: 5 | B17: =B16-C16 -> 154 | C17: 154 | D17: =B17-C17 -> 0
A19: Tableau d'amortissement : site internet
A20: Année | B20: VR | C20: Amortissements | D20: VNC
A21: 1 | B21: 10000 | C21: 2000 | D21: 4000
A22: 2 | B22: =B21-C21 -> 8000 | C22: 2000 | D22: =B22-C22 -> 6000
A23: 3 | B23: =B22-C22 -> 6000 | C23: 2000 | D23: =B23-C23 -> 4000
A24: 4 | B24: =B23-C23 -> 4000 | C24: 2000 | D24: =B24-C24 -> 2000
A25: 5 | B25: =B24-C24 -> 2000 | C25: 2000 | D25: =B25-C25 -> 0
A27: Tableau d'amortissement : Équipement (chambre froid+étuve+contenaire)
A28: Année | B28: VR | C28: Amortissements | D28: VNC
A29: 1 | B29: =9400+1000+300 -> 10700 | C29: =B29/5 -> 2140 | D29: 4000
A30: 2 | B30: =B29-C29 -> 8560 | C30: 2140 | D30: =B30-C30 -> 6420
A31: 3 | B31: =B30-C30 -> 6420 | C31: 2140 | D31: =B31-C31 -> 4280
A32: 4 | B32: =B31-C31 -> 4280 | C32: 2140 | D32: =B32-C32 -> 2140
A33: 5 | B33: =B32-C32 -> 2140 | C33: 2140 | D33: =B33-C33 -> 0

Sheet Plan de financement
A1: Plan de financement Test | B1: N | C1: N+1 | D1: N+2 | F1: Plan de financement Final | G1: N | H1: N+1 | I1: N+2
A2: Emplois | B2: =+SUM(B3:B7) -> 60279.922 | C2: =+SUM(C3:C7) -> 2890.4941 | D2: =+SUM(D3:D7) -> 4143.0416 | F2: Emplois | G2: =+SUM(G3:G7) -> 60279.922 | H2: =+SUM(H3:H7) -> 2890.4941 | I2: =+SUM(I3:I7) -> 4143.0416
A3: Total Acquisition immo | B3: =21740 -> 21740 | F3: Total Acquisition immo | G3: =21740 -> 21740
A4: Augmentation BFR | B4: 38539.922 | C4: 2890.4941 | D4: 4143.0416 | F4: Augmentation BFR | G4: 38539.922 | H4: 2890.4941 | I4: 4143.0416
A5: Remboursement emprunt | B5: 0 | C5: 0 | D5: 0 | F5: Remboursement emprunt | G5: 0 | H5: 0 | I5: 0
A6: Remboursement compte courant | B6: 0 | C6: 0 | D6: 0 | F6: Remboursement compte courant | G6: 0 | H6: 0 | I6: 0
A7: Charges d'intérêts emprunt | B7: 0 | C7: 0 | D7: 0 | F7: Charges d'intérêts emprunt | G7: 0 | H7: 0 | I7: 0
A8: Ressources | B8: 47529 | C8: 28017 | D8: 26498 | F8: Ressources | G8: =SUM(G9:G11) -> 64250.046 | H8: =SUM(H9:H11) -> 37506.733 | I8: =SUM(I9:I11) -> 58654.29
A9: CAF | B9: =B30 -> 24250.046 | C9: =C30 -> 37506.733 | D9: =D30 -> 58654.29 | F9: CAF | G9: =B30 -> 24250.046 | H9: =C30 -> 37506.733 | I9: =D30 -> 58654.29
A10: Suvbention de l'etat | B10: 20000 | F10: Suvbention de l'etat | G10: 40000
A11: Augmentation compte courant | B11: 0 | C11: 0 | D11: 0 | F11: Augmentation compte courant | G11: 0 | H11: 0 | I11: 0
A12: Ecart annuel | B12: =+B8-B2 -> -12750.922 | C12: =+C8-C2 -> 25126.506 | D12: =+D8-D2 -> 22354.958 | F12: Ecart annuel | G12: =+G8-G2 -> 3970.1239 | H12: =+H8-H2 -> 34616.239 | I12: =+I8-I2 -> 54511.248
A13: Trésorerie initial | B13: 0 | C13: =B14 -> -12750.922 | D13: =C14 -> 12375.584 | F13: Trésorerie initial | G13: 0 | H13: =G14 -> 3970.1239 | I13: =H14 -> 38586.363
A14: Trésorerie final | B14: =B13+B12 -> -12750.922 | C14: =C13+C12 -> 12375.584 | D14: =D13+D12 -> 34730.542 | F14: Trésorerie final | G14: =G13+G12 -> 3970.1239 | H14: =H13+H12 -> 38586.363 | I14: =I13+I12 -> 93097.611
A16: BFR | B16: N | C16: N+1 | D16: N+2
A17: CA | B17: 308319.38 | C17: 331443.33 | D17: 364587.66 | F17: Au début, nous étions partis sur une demande de subvention qui reposait sur le montant total des investissements. Cependant, au regard de notre trésorerie la première année, nous nous sommes rendus compte que ce n'était pas suffisant (-12k). Nous avons donc augmenté cette demande de subvention afin d'avoir une meilleure stabilité financière. Bien évidemment, si cette demande se voit refusée, il est tout à fait possible de varier avec un autre mode de financement et ainsi passer par un prêt bancaire de 20k.
A18: 45J CA | B18: =(B24/360)*45 -> 38539.922 | C18: =(C24/360)*45 -> 41430.416 | D18: =(D24/360)*45 -> 45573.458
A19: variation | B19: =B18 -> 38539.922 | C19: =C18-B18 -> 2890.4941 | D19: =D18-C18 -> 4143.0416
A21: CA prévisionnel | B21: N | C21: N+1 | D21: N+2
A22: CA Click and collect | B22: 293637.5 | C22: 293637.5 | D22: 293637.5
A23: Augmentation Click and collect | B23: 0.05 | C23: 0.075 | D23: 0.1
A24: CA | B24: =B22*1.05 -> 308319.38 | C24: =B24*1.075 -> 331443.33 | D24: =C24*1.1 -> 364587.66
A26: CAF prévisionnel | B26: N | C26: N+1 | D26: N+2
A27: EBE | B27: ='Compte de résultat'!C18 -> 32638.728 | C27: ='Compte de résultat'!D18 -> 47076.769 | D27: ='Compte de résultat'!E18 -> 69980.507
A28: IS | B28: 8388.6819 | C28: 9570.0361 | D28: 11326.217
A29: Charges Financières | B29: 0 | C29: 0 | D29: 0
A30: CAF | B30: =B27-(B28+B29) -> 24250.046 | C30: =C27-(C28+C29) -> 37506.733 | D30: =D27-(D28+D29) -> 58654.29

Sheet Plan de trésorerie N
A1: N | B1: Janvier | C1: Février | D1: Mars | E1: Avril | F1: Mai | G1: Juin | H1: Juillet | I1: Août | J1: Septembre | K1: Octobre | L1: Novembre | M1: Décembre | O1: Explications :
A2: Encaissements | O2: CA : Pas de CA Juillet / Août (vacance)
A3: CA | B3: =308319/10 -> 30831.9 | C3: =308319/10 -> 30831.9 | D3: =308319/10 -> 30831.9 | E3: =308319/10 -> 30831.9 | F3: =308319/10 -> 30831.9 | G3: =308319/10 -> 30831.9 | J3: =308319/10 -> 30831.9 | K3: =308319/10 -> 30831.9 | L3: =308319/10 -> 30831.9 | M3: =308319/10 -> 30831.9 | O3: Achat réglé sous 30 jours
A4: Subvention | B4: =40000 -> 40000
A5: TVA collectée | B5: =B35 -> 3083.19 | C5: =C35 -> 3083.19 | D5: =D35 -> 3083.19 | E5: =E35 -> 3083.19 | F5: =F35 -> 3083.19 | G5: =G35 -> 3083.19 | H5: =H35 -> 0 | I5: =I35 -> 0 | ... M5: =M35 -> 3083.19
A6: Décaissement
A7: Achats | C7: =189735/10 -> 18973.5 | D7: =189735/10 -> 18973.5 | E7: =189735/10 -> 18973.5 | F7: =189735/10 -> 18973.5 | G7: =189735/10 -> 18973.5 | H7: =189735/10 -> 18973.5 | K7: =189735/10 -> 18973.5 | L7: =189735/10 -> 18973.5 | M7: =189735/10 -> 18973.5
A8: Immo | B8: =21740 -> 21740
A9: Salaires | B9: ='Compte de résultat'!C71 -> 1304.5225 | C9: =B9 -> 1304.5225 | D9: =C9 -> 1304.5225 | E9: =D9 -> 1304.5225 | F9: =E9 -> 1304.5225 | G9: =F9 -> 1304.5225 | J9: =G9 -> 1304.5225 | K9: =J9 -> 1304.5225 | L9: =K9 -> 1304.5225 | M9: =L9 -> 1304.5225
A10: Charges sociales | B10: =B9*0.28 -> 365.2663 | C10: =C9*0.28 -> 365.2663 | D10: =D9*0.28 -> 365.2663 | E10: =E9*0.28 -> 365.2663 | F10: =F9*0.28 -> 365.2663 | G10: =G9*0.28 -> 365.2663 | J10: =J9*0.28 -> 365.2663 | K10: =K9*0.28 -> 365.2663 | L10: =L9*0.28 -> 365.2663 | M10: =M9*0.28 -> 365.2663
A11: Charges patronales | B11: =B9*0.4 -> 521.809 | C11: =C9*0.4 -> 521.809 | D11: =D9*0.4 -> 521.809 | E11: =E9*0.4 -> 521.809 | F11: =F9*0.4 -> 521.809 | G11: =G9*0.4 -> 521.809 | J11: =J9*0.4 -> 521.809 | K11: =K9*0.4 -> 521.809 | L11: =L9*0.4 -> 521.809 | M11: =M9*0.4 -> 521.809
A12: Impôts
A13: Rbt crédit
A14: Charges d'intérêts
A15: Charges externes
A16: Eau | B16: ='Compte de résultat'!C10/10 -> 42.6426 | C16: =B16 -> 42.6426 | D16: =C16 -> 42.6426 | E16: =D16 -> 42.6426 | F16: =E16 -> 42.6426 | G16: =F16 -> 42.6426 | J16: =G16 -> 42.6426 | K16: =J16 -> 42.6426 | L16: =K16 -> 42.6426 | M16: =L16 -> 42.6426
A17: Electricité | B17: ='Compte de résultat'!C7/10 -> 4021.0363 | C17: =B17 -> 4021.0363 | D17: =C17 -> 4021.0363 | E17: =D17 -> 4021.0363 | F17: =E17 -> 4021.0363 | G17: =F17 -> 4021.0363 | I17: =H17 -> 0 | J17: =G17 -> 4021.0363 | K17: =J17 -> 4021.0363 | L17: =K17 -> 4021.0363 | M17: =L17 -> 4021.0363
A18: Loyer, assurance | B18: ='Compte de résultat'!C9/12 -> 200 | C18: =B18 -> 200 | D18: =C18 -> 200 | E18: =D18 -> 200 | F18: =E18 -> 200 | G18: =F18 -> 200 | H18: =G18 -> 200 | I18: =H18 -> 200 | J18: =I18 -> 200 | ... M18: =L18 -> 200
A19: Budget marketing et communication | B19: ='Compte de résultat'!C12/10 -> 500 | C19: =B19 -> 500 | D19: =C19 -> 500 | E19: =D19 -> 500 | F19: =E19 -> 500 | G19: =F19 -> 500 | J19: =G19 -> 500 | K19: =J19 -> 500 | L19: =K19 -> 500 | M19: =L19 -> 500
A20: Frais de communication | B20: ='Compte de résultat'!C10 -> 426.426 | C20: =B20 -> 426.426 | D20: =C20 -> 426.426 | E20: =D20 -> 426.426 | F20: =E20 -> 426.426 | G20: =F20 -> 426.426 | H20: =G20 -> 426.426 | I20: =H20 -> 426.426 | J20: =I20 -> 426.426 | ... M20: =L20 -> 426.426
A21: Charges financières
A22: TVA sur achats | B22: =B36 -> 0 | C22: =C36 -> 1897.35 | D22: =D36 -> 1897.35 | E22: =E36 -> 1897.35 | F22: =F36 -> 1897.35 | G22: =G36 -> 1897.35 | H22: =H36 -> 1897.35 | I22: =I36 -> 0 | ... M22: =M36 -> 1897.35
A23: TVA sur immo | B23: =B37 -> 4348 | C23: =C37 -> 0 | D23: =D37 -> 0 | E23: =E37 -> 0 | F23: =F37 -> 0 | G23: =G37 -> 0 | H23: =H37 -> 0 | I23: =I37 -> 0 | ... M23: =M37 -> 0
A24: Trésorerie
A25: Tresorerie d'ouverture | C25: =B27 -> 40445.387 | D25: =C27 -> 46107.925 | E25: =D27 -> 51770.462 | F25: =E27 -> 57432.999 | G25: =F27 -> 63095.537 | H25: =G27 -> 68758.074 | I25: =H27 -> 47260.798 | J25: =I27 -> 46634.372 | ... M25: =L27 -> 84492.834
A26: Trésorerie par mois de cloture | B26: =SUM(B3:B5)-SUM(B7:B23) -> 40445.387 | C26: =SUM(C3:C5)-SUM(C7:C23) -> 5662.5373 | D26: =SUM(D3:D5)-SUM(D7:D23) -> 5662.5373 | E26: =SUM(E3:E5)-SUM(E7:E23) -> 5662.5373 | F26: =SUM(F3:F5)-SUM(F7:F23) -> 5662.5373 | G26: =SUM(G3:G5)-SUM(G7:G23) -> 5662.5373 | H26: =SUM(H3:H5)-SUM(H7:H23) -> -21497.276 | I26: =SUM(I3:I5)-SUM(I7:I23) -> -626.426 | ... M26: =SUM(M3:M5)-SUM(M7:M23) -> 5662.5373
A27: Tresorerie cumulée de cloture | B27: =SUM(B3:B5)-SUM(B7:B23)+B25 -> 40445.387 | C27: =SUM(C3:C5)-SUM(C7:C23)+C25 -> 46107.925 | D27: =SUM(D3:D5)-SUM(D7:D23)+D25 -> 51770.462 | E27: =SUM(E3:E5)-SUM(E7:E23)+E25 -> 57432.999 | F27: =SUM(F3:F5)-SUM(F7:F23)+F25 -> 63095.537 | G27: =SUM(G3:G5)-SUM(G7:G23)+G25 -> 68758.074 | H27: =SUM(H3:H5)-SUM(H7:H23)+H25 -> 47260.798 | I27: =SUM(I3:I5)-SUM(I7:I23)+I25 -> 46634.372 | ... M27: =SUM(M3:M5)-SUM(M7:M23)+M25 -> 90155.371
A33: TVA décaissé | B33: Janvier | C33: Février | D33: Mars | E33: Avril | F33: Mai | G33: Juin | H33: Juillet | I33: Août | J33: Septembre | K33: Octobre | L33: Novembre | M33: Décembre
A34: Poste TVA à déc. | C34: =B38 -> -1264.81 | D34: =C38 -> 1185.84 | E34: =D38 -> 1185.84 | F34: =E38 -> 1185.84 | G34: =F38 -> 1185.84 | H34: =G38 -> 1185.84 | I34: =H38 -> -1897.35 | J34: =I38 -> 0 | ... M34: =L38 -> 1185.84
A35: TVA collectéé sur ventes | B35: =B3*0.1 -> 3083.19 | C35: =C3*0.1 -> 3083.19 | D35: =D3*0.1 -> 3083.19 | E35: =E3*0.1 -> 3083.19 | F35: =F3*0.1 -> 3083.19 | G35: =G3*0.1 -> 3083.19 | H35: =H3*0.1 -> 0 | I35: =I3*0.1 -> 0 | ... M35: =M3*0.1 -> 3083.19
A36: TVA déd sur achats | C36: =C7*10% -> 1897.35 | D36: =D7*10% -> 1897.35 | E36: =E7*10% -> 1897.35 | F36: =F7*10% -> 1897.35 | G36: =G7*10% -> 1897.35 | H36: =H7*10% -> 1897.35 | I36: =I7*10% -> 0 | J36: =J7*10% -> 0 | ... M36: =M7*10% -> 1897.35
A37: TVA déd sur immo | B37: =B8*0.2 -> 4348 | C37: =C8*0.2 -> 0 | D37: =D8*0.2 -> 0 | E37: =E8*0.2 -> 0 | F37: =F8*0.2 -> 0 | G37: =G8*0.2 -> 0 | H37: =H8*0.2 -> 0 | I37: =I8*0.2 -> 0 | ... M37: =M8*0.2 -> 0
A38: TVA à décaisser | B38: =B35-B36-B37 -> -1264.81 | C38: =C35-C36-C37 -> 1185.84 | D38: =D35-D36-D37 -> 1185.84 | E38: =E35-E36-E37 -> 1185.84 | F38: =F35-F36-F37 -> 1185.84 | G38: =G35-G36-G37 -> 1185.84 | H38: =H35-H36-H37 -> -1897.35 | I38: =I35-I36-I37 -> 0 | ... M38: =M35-M36-M37 -> 1185.84
A39: Décaissement de la TVA | B39: =B34 -> 0 | C39: =C34 -> -1264.81 | D39: =D34 -> 1185.84 | E39: =E34 -> 1185.84 | F39: =F34 -> 1185.84 | G39: =G34 -> 1185.84 | H39: =H34 -> 1185.84 | I39: =I34 -> -1897.35 | ... M39: =M34 -> 1185.84

Sheet Plan de trésorerie N+1
A1: N | B1: Janvier | C1: Février | D1: Mars | E1: Avril | F1: Mai | G1: Juin | H1: Juillet | I1: Août | J1: Septembre | K1: Octobre | L1: Novembre | M1: Décembre | O1: Explications :
A2: Encaissements | O2: CA : Pas de CA Juillet / Août (vacance)
A3: CA | B3: =331443/10 -> 33144.3 | C3: =331443/10 -> 33144.3 | D3: =331443/10 -> 33144.3 | E3: =331443/10 -> 33144.3 | F3: =331443/10 -> 33144.3 | G3: =331443/10 -> 33144.3 | J3: =331443/10 -> 33144.3 | K3: =331443/10 -> 33144.3 | L3: =331443/10 -> 33144.3 | M3: =331443/10 -> 33144.3 | O3: Achat réglé sous 30 jours
A4: TVA collectée | B4: =B34 -> 3314.43 | C4: =C34 -> 3314.43 | D4: =D34 -> 3314.43 | E4: =E34 -> 3314.43 | F4: =F34 -> 3314.43 | G4: =G34 -> 3314.43 | H4: =H34 -> 0 | I4: =I34 -> 0 | ... M4: =M34 -> 3314.43
A5: Décaissement
A6: Achats | B6: ='Compte de résultat'!D4/10 -> 19425.25 | C6: =B6 -> 19425.25 | D6: =C6 -> 19425.25 | E6: =D6 -> 19425.25 | F6: =E6 -> 19425.25 | G6: =F6 -> 19425.25 | H6: =G6 -> 19425.25 | J6: =I6 -> 0 | K6: =H6 -> 19425.25 | L6: =K6 -> 19425.25 | M6: =L6 -> 19425.25
A7: Immo
A8: Salaires | B8: ='Compte de résultat'!D71 -> 1330.6129 | C8: =B8 -> 1330.6129 | D8: =C8 -> 1330.6129 | E8: =D8 -> 1330.6129 | F8: =E8 -> 1330.6129 | G8: =F8 -> 1330.6129 | I8: =H8 -> 0 | J8: =G8 -> 1330.6129 | K8: =J8 -> 1330.6129 | L8: =K8 -> 1330.6129 | M8: =L8 -> 1330.6129
A9: Charges sociales | B9: =B8*0.28 -> 372.57162 | C9: =C8*0.28 -> 372.57162 | D9: =D8*0.28 -> 372.57162 | E9: =E8*0.28 -> 372.57162 | F9: =F8*0.28 -> 372.57162 | G9: =G8*0.28 -> 372.57162 | J9: =J8*0.28 -> 372.57162 | K9: =K8*0.28 -> 372.57162 | L9: =L8*0.28 -> 372.57162 | M9: =M8*0.28 -> 372.57162
A10: Charges patronales | B10: =B8*0.4 -> 532.24518 | C10: =C8*0.4 -> 532.24518 | D10: =D8*0.4 -> 532.24518 | E10: =E8*0.4 -> 532.24518 | F10: =F8*0.4 -> 532.24518 | G10: =G8*0.4 -> 532.24518 | J10: =J8*0.4 -> 532.24518 | K10: =K8*0.4 -> 532.24518 | L10: =L8*0.4 -> 532.24518 | M10: =M8*0.4 -> 532.24518
A11: Impôts
A12: Rbt crédit
A13: Charges d'intérêts
A14: Charges externes
A15: Eau | B15: ='Compte de résultat'!D10/10 -> 45.840795 | C15: =B15 -> 45.840795 | D15: =C15 -> 45.840795 | E15: =D15 -> 45.840795 | F15: =E15 -> 45.840795 | G15: =F15 -> 45.840795 | J15: =G15 -> 45.840795 | K15: =J15 -> 45.840795 | L15: =K15 -> 45.840795 | M15: =L15 -> 45.840795
A16: Electricité | B16: ='Compte de résultat'!D7/10 -> 4322.614 | C16: =B16 -> 4322.614 | D16: =C16 -> 4322.614 | E16: =D16 -> 4322.614 | F16: =E16 -> 4322.614 | G16: =F16 -> 4322.614 | I16: =H16 -> 0 | J16: =G16 -> 4322.614 | K16: =J16 -> 4322.614 | L16: =K16 -> 4322.614 | M16: =L16 -> 4322.614
A17: Loyer, assurance | B17: ='Compte de résultat'!C9/12 -> 200 | C17: =B17 -> 200 | D17: =C17 -> 200 | E17: =D17 -> 200 | F17: =E17 -> 200 | G17: =F17 -> 200 | H17: =G17 -> 200 | I17: =H17 -> 200 | J17: =I17 -> 200 | ... M17: =L17 -> 200
A18: Budget marketing et communication | B18: ='Compte de résultat'!C12/10 -> 500 | C18: =B18 -> 500 | D18: =C18 -> 500 | E18: =D18 -> 500 | F18: =E18 -> 500 | G18: =F18 -> 500 | J18: =G18 -> 500 | K18: =J18 -> 500 | L18: =K18 -> 500 | M18: =L18 -> 500
A19: Frais de communication | B19: ='Compte de résultat'!C10 -> 426.426 | C19: =B19 -> 426.426 | D19: =C19 -> 426.426 | E19: =D19 -> 426.426 | F19: =E19 -> 426.426 | G19: =F19 -> 426.426 | H19: =G19 -> 426.426 | I19: =H19 -> 426.426 | J19: =I19 -> 426.426 | ... M19: =L19 -> 426.426
A20: Charges financières
A21: TVA sur achats | B21: =B35 -> 0 | C21: =C35 -> 1942.525 | D21: =D35 -> 1942.525 | E21: =E35 -> 1942.525 | F21: =F35 -> 1942.525 | G21: =G35 -> 1942.525 | H21: =H35 -> 1942.525 | I21: =I35 -> 0 | ... M21: =M35 -> 1942.525
A22: TVA sur immo | B22: =B36 -> 0 | C22: =C36 -> 0 | D22: =D36 -> 0 | E22: =E36 -> 0 | F22: =F36 -> 0 | G22: =G36 -> 0 | H22: =H36 -> 0 | I22: =I36 -> 0 | ... M22: =M36 -> 0
A23: Trésorerie
A24: Tresorerie d'ouverture | C24: =B26 -> 9303.1694 | D24: =C26 -> 16663.814 | E24: =D26 -> 24024.458 | F24: =E26 -> 31385.103 | G24: =F26 -> 38745.747 | H24: =G26 -> 46106.392 | I24: =H26 -> 24112.191 | J24: =I26 -> 23485.765 | ... M24: =L26 -> 66935.473
A25: Trésorerie par mois de cloture | B25: =SUM(B3:B4)-SUM(B6:B22) -> 9303.1694 | C25: =SUM(C3:C4)-SUM(C6:C22) -> 7360.6444 | D25: =SUM(D3:D4)-SUM(D6:D22) -> 7360.6444 | E25: =SUM(E3:E4)-SUM(E6:E22) -> 7360.6444 | F25: =SUM(F3:F4)-SUM(F6:F22) -> 7360.6444 | G25: =SUM(G3:G4)-SUM(G6:G22) -> 7360.6444 | H25: =SUM(H3:H4)-SUM(H6:H22) -> -21994.201 | I25: =SUM(I3:I4)-SUM(I6:I22) -> -626.426 | ... M25: =SUM(M3:M4)-SUM(M6:M22) -> 7360.6444
A26: Tresorerie cumulée de cloture | B26: =SUM(B3:B4)-SUM(B6:B22)+B24 -> 9303.1694 | C26: =SUM(C3:C4)-SUM(C6:C22)+C24 -> 16663.814 | D26: =SUM(D3:D4)-SUM(D6:D22)+D24 -> 24024.458 | E26: =SUM(E3:E4)-SUM(E6:E22)+E24 -> 31385.103 | F26: =SUM(F3:F4)-SUM(F6:F22)+F24 -> 38745.747 | G26: =SUM(G3:G4)-SUM(G6:G22)+G24 -> 46106.392 | H26: =SUM(H3:H4)-SUM(H6:H22)+H24 -> 24112.191 | I26: =SUM(I3:I4)-SUM(I6:I22)+I24 -> 23485.765 | ... M26: =SUM(M3:M4)-SUM(M6:M22)+M24 -> 74296.117
A32: TVA décaissé | B32: Janvier | C32: Février | D32: Mars | E32: Avril | F32: Mai | G32: Juin | H32: Juillet | I32: Août | J32: Septembre | K32: Octobre | L32: Novembre | M32: Décembre
A33: Poste TVA à déc. | C33: =B37 -> 3314.43 | D33: =C37 -> 1371.905 | E33: =D37 -> 1371.905 | F33: =E37 -> 1371.905 | G33: =F37 -> 1371.905 | H33: =G37 -> 1371.905 | I33: =H37 -> -1942.525 | J33: =I37 -> 0 | ... M33: =L37 -> 1371.905
A34: TVA collectéé sur ventes | B34: =B3*0.1 -> 3314.43 | C34: =C3*0.1 -> 3314.43 | D34: =D3*0.1 -> 3314.43 | E34: =E3*0.1 -> 3314.43 | F34: =F3*0.1 -> 3314.43 | G34: =G3*0.1 -> 3314.43 | H34: =H3*0.1 -> 0 | I34: =I3*0.1 -> 0 | ... M34: =M3*0.1 -> 3314.43
A35: TVA déd sur achats | C35: =C6*10% -> 1942.525 | D35: =D6*10% -> 1942.525 | E35: =E6*10% -> 1942.525 | F35: =F6*10% -> 1942.525 | G35: =G6*10% -> 1942.525 | H35: =H6*10% -> 1942.525 | I35: =I6*10% -> 0 | J35: =J6*10% -> 0 | ... M35: =M6*10% -> 1942.525
A36: TVA déd sur immo | B36: =B7*0.2 -> 0 | C36: =C7*0.2 -> 0 | D36: =D7*0.2 -> 0 | E36: =E7*0.2 -> 0 | F36: =F7*0.2 -> 0 | G36: =G7*0.2 -> 0 | H36: =H7*0.2 -> 0 | I36: =I7*0.2 -> 0 | ... M36: =M7*0.2 -> 0
A37: TVA à décaisser | B37: =B34-B35-B36 -> 3314.43 | C37: =C34-C35-C36 -> 1371.905 | D37: =D34-D35-D36 -> 1371.905 | E37: =E34-E35-E36 -> 1371.905 | F37: =F34-F35-F36 -> 1371.905 | G37: =G34-G35-G36 -> 1371.905 | H37: =H34-H35-H36 -> -1942.525 | I37: =I34-I35-I36 -> 0 | ... M37: =M34-M35-M36 -> 1371.905
A38: Décaissement de la TVA | B38: =B33 -> 0 | C38: =C33 -> 3314.43 | D38: =D33 -> 1371.905 | E38: =E33 -> 1371.905 | F38: =F33 -> 1371.905 | G38: =G33 -> 1371.905 | H38: =H33 -> 1371.905 | I38: =I33 -> -1942.525 | ... M38: =M33 -> 1371.905

Sheet Plan de trésorerie N+2
A1: N | B1: Janvier | C1: Février | D1: Mars | E1: Avril | F1: Mai | G1: Juin | H1: Juillet | I1: Août | J1: Septembre | K1: Octobre | L1: Novembre | M1: Décembre | O1: Explications :
A2: Encaissements | O2: CA : Pas de CA Juillet / Août (vacance)
A3: CA | B3: ='Compte de résultat'!E3/10 -> 36458.766 | C3: =B3 -> 36458.766 | D3: =C3 -> 36458.766 | E3: =D3 -> 36458.766 | F3: =E3 -> 36458.766 | G3: =F3 -> 36458.766 | I3: =H3 -> 0 | J3: =G3 -> 36458.766 | K3: =J3 -> 36458.766 | L3: =K3 -> 36458.766 | M3: =L3 -> 36458.766 | O3: Achat réglé sous 30 jours
A4: TVA collectée | B4: =B34 -> 3645.8766 | C4: =C34 -> 3645.8766 | D4: =D34 -> 3645.8766 | E4: =E34 -> 3645.8766 | F4: =F34 -> 3645.8766 | G4: =G34 -> 3645.8766 | H4: =H34 -> 0 | I4: =I34 -> 0 | ... M4: =M34 -> 3645.8766
A5: Décaissement
A6: Achats | B6: ='Compte de résultat'!E4/10 -> 19877 | C6: =B6 -> 19877 | D6: =C6 -> 19877 | E6: =D6 -> 19877 | F6: =E6 -> 19877 | G6: =F6 -> 19877 | H6: =G6 -> 19877 | J6: =I6 -> 0 | K6: =H6 -> 19877 | L6: =K6 -> 19877 | M6: =L6 -> 19877
A7: Immo
A8: Salaires | B8: ='Compte de résultat'!E71 -> 1357.2252 | C8: =B8 -> 1357.2252 | D8: =C8 -> 1357.2252 | E8: =D8 -> 1357.2252 | F8: =E8 -> 1357.2252 | G8: =F8 -> 1357.2252 | I8: =H8 -> 0 | J8: =G8 -> 1357.2252 | K8: =J8 -> 1357.2252 | L8: =K8 -> 1357.2252 | M8: =L8 -> 1357.2252
A9: Charges sociales | B9: =B8*0.28 -> 380.02306 | C9: =C8*0.28 -> 380.02306 | D9: =D8*0.28 -> 380.02306 | E9: =E8*0.28 -> 380.02306 | F9: =F8*0.28 -> 380.02306 | G9: =G8*0.28 -> 380.02306 | J9: =J8*0.28 -> 380.02306 | K9: =K8*0.28 -> 380.02306 | L9: =L8*0.28 -> 380.02306 | M9: =M8*0.28 -> 380.02306
A10: Charges patronales | B10: =B8*0.4 -> 542.89008 | C10: =C8*0.4 -> 542.89008 | D10: =D8*0.4 -> 542.89008 | E10: =E8*0.4 -> 542.89008 | F10: =F8*0.4 -> 542.89008 | G10: =G8*0.4 -> 542.89008 | J10: =J8*0.4 -> 542.89008 | K10: =K8*0.4 -> 542.89008 | L10: =L8*0.4 -> 542.89008 | M10: =M8*0.4 -> 542.89008
A11: Impôts
A12: Rbt crédit
A13: Charges d'intérêts
A14: Charges externes
A15: Eau | B15: ='Compte de résultat'!E10/10 -> 50.424875 | C15: =B15 -> 50.424875 | D15: =C15 -> 50.424875 | E15: =D15 -> 50.424875 | F15: =E15 -> 50.424875 | G15: =F15 -> 50.424875 | J15: =G15 -> 50.424875 | K15: =J15 -> 50.424875 | L15: =K15 -> 50.424875 | M15: =L15 -> 50.424875
A16: Electricité | B16: ='Compte de résultat'!E7/10 -> 4754.8754 | C16: =B16 -> 4754.8754 | D16: =C16 -> 4754.8754 | E16: =D16 -> 4754.8754 | F16: =E16 -> 4754.8754 | G16: =F16 -> 4754.8754 | I16: =H16 -> 0 | J16: =G16 -> 4754.8754 | K16: =J16 -> 4754.8754 | L16: =K16 -> 4754.8754 | M16: =L16 -> 4754.8754
A17: Loyer, assurance | B17: ='Compte de résultat'!C9/12 -> 200 | C17: =B17 -> 200 | D17: =C17 -> 200 | E17: =D17 -> 200 | F17: =E17 -> 200 | G17: =F17 -> 200 | H17: =G17 -> 200 | I17: =H17 -> 200 | J17: =I17 -> 200 | ... M17: =L17 -> 200
A18: Budget marketing et communication | B18: ='Compte de résultat'!C12/10 -> 500 | C18: =B18 -> 500 | D18: =C18 -> 500 | E18: =D18 -> 500 | F18: =E18 -> 500 | G18: =F18 -> 500 | J18: =G18 -> 500 | K18: =J18 -> 500 | L18: =K18 -> 500 | M18: =L18 -> 500
A19: Frais de communication | B19: ='Compte de résultat'!C10 -> 426.426 | C19: =B19 -> 426.426 | D19: =C19 -> 426.426 | E19: =D19 -> 426.426 | F19: =E19 -> 426.426 | G19: =F19 -> 426.426 | H19: =G19 -> 426.426 | I19: =H19 -> 426.426 | J19: =I19 -> 426.426 | ... M19: =L19 -> 426.426
A20: Charges financières
A21: TVA sur achats | B21: =B35 -> 0 | C21: =C35 -> 1987.7 | D21: =D35 -> 1987.7 | E21: =E35 -> 1987.7 | F21: =F35 -> 1987.7 | G21: =G35 -> 1987.7 | H21: =H35 -> 1987.7 | I21: =I35 -> 0 | ... M21: =M35 -> 1987.7
A22: TVA sur immo | B22: =B36 -> 0 | C22: =C36 -> 0 | D22: =D36 -> 0 | E22: =E36 -> 0 | F22: =F36 -> 0 | G22: =G36 -> 0 | H22: =H36 -> 0 | I22: =I36 -> 0 | ... M22: =M36 -> 0
A23: Trésorerie
A24: Tresorerie d'ouverture | C24: =B26 -> 12015.778 | D24: =C26 -> 22043.856 | E24: =D26 -> 32071.934 | F24: =E26 -> 42100.012 | G24: =F26 -> 52128.09 | H24: =G26 -> 62156.168 | I24: =H26 -> 39665.042 | J24: =I26 -> 39038.616 | ... M24: =L26 -> 90987.55
A25: Trésorerie par mois de cloture | B25: =SUM(B3:B4)-SUM(B6:B22) -> 12015.778 | C25: =SUM(C3:C4)-SUM(C6:C22) -> 10028.078 | D25: =SUM(D3:D4)-SUM(D6:D22) -> 10028.078 | E25: =SUM(E3:E4)-SUM(E6:E22) -> 10028.078 | F25: =SUM(F3:F4)-SUM(F6:F22) -> 10028.078 | G25: =SUM(G3:G4)-SUM(G6:G22) -> 10028.078 | H25: =SUM(H3:H4)-SUM(H6:H22) -> -22491.126 | I25: =SUM(I3:I4)-SUM(I6:I22) -> -626.426 | ... M25: =SUM(M3:M4)-SUM(M6:M22) -> 10028.078
A26: Tresorerie cumulée de cloture | B26: =SUM(B3:B4)-SUM(B6:B22)+B24 -> 12015.778 | C26: =SUM(C3:C4)-SUM(C6:C22)+C24 -> 22043.856 | D26: =SUM(D3:D4)-SUM(D6:D22)+D24 -> 32071.934 | E26: =SUM(E3:E4)-SUM(E6:E22)+E24 -> 42100.012 | F26: =SUM(F3:F4)-SUM(F6:F22)+F24 -> 52128.09 | G26: =SUM(G3:G4)-SUM(G6:G22)+G24 -> 62156.168 | H26: =SUM(H3:H4)-SUM(H6:H22)+H24 -> 39665.042 | I26: =SUM(I3:I4)-SUM(I6:I22)+I24 -> 39038.616 | ... M26: =SUM(M3:M4)-SUM(M6:M22)+M24 -> 101015.63
A32: TVA décaissé | B32: Janvier | C32: Février | D32: Mars | E32: Avril | F32: Mai | G32: Juin | H32: Juillet | I32: Août | J32: Septembre | K32: Octobre | L32: Novembre | M32: Décembre
A33: Poste TVA à déc. | C33: =B37 -> 3645.8766 | D33: =C37 -> 1658.1766 | E33: =D37 -> 1658.1766 | F33: =E37 -> 1658.1766 | G33: =F37 -> 1658.1766 | H33: =G37 -> 1658.1766 | I33: =H37 -> -1987.7 | J33: =I37 -> 0 | ... M33: =L37 -> 1658.1766
A34: TVA collectéé sur ventes | B34: =B3*0.1 -> 3645.8766 | C34: =C3*0.1 -> 3645.8766 | D34: =D3*0.1 -> 3645.8766 | E34: =E3*0.1 -> 3645.8766 | F34: =F3*0.1 -> 3645.8766 | G34: =G3*0.1 -> 3645.8766 | H34: =H3*0.1 -> 0 | I34: =I3*0.1 -> 0 | ... M34: =M3*0.1 -> 3645.8766
A35: TVA déd sur achats | C35: =C6*10% -> 1987.7 | D35: =D6*10% -> 1987.7 | E35: =E6*10% -> 1987.7 | F35: =F6*10% -> 1987.7 | G35: =G6*10% -> 1987.7 | H35: =H6*10% -> 1987.7 | I35: =I6*10% -> 0 | J35: =J6*10% -> 0 | ... M35: =M6*10% -> 1987.7
A36: TVA déd sur immo | B36: =B7*0.2 -> 0 | C36: =C7*0.2 -> 0 | D36: =D7*0.2 -> 0 | E36: =E7*0.2 -> 0 | F36: =F7*0.2 -> 0 | G36: =G7*0.2 -> 0 | H36: =H7*0.2 -> 0 | I36: =I7*0.2 -> 0 | ... M36: =M7*0.2 -> 0
A37: TVA à décaisser | B37: =B34-B35-B36 -> 3645.8766 | C37: =C34-C35-C36 -> 1658.1766 | D37: =D34-D35-D36 -> 1658.1766 | E37: =E34-E35-E36 -> 1658.1766 | F37: =F34-F35-F36 -> 1658.1766 | G37: =G34-G35-G36 -> 1658.1766 | H37: =H34-H35-H36 -> -1987.7 | I37: =I34-I35-I36 -> 0 | ... M37: =M34-M35-M36 -> 1658.1766
A38: Décaissement de la TVA | B38: =B33 -> 0 | C38: =C33 -> 3645.8766 | D38: =D33 -> 1658.1766 | E38: =E33 -> 1658.1766 | F38: =F33 -> 1658.1766 | G38: =G33 -> 1658.1766 | H38: =H33 -> 1658.1766 | I38: =I33 -> -1987.7 | ... M38: =M33 -> 1658.1766
